<?xml version="1.0" ?>
<!-- =================================================================================== -->
<!-- |    This document was autogenerated by xacro from tm700_robot.urdf.xacro         | -->
<!-- |    EDITING THIS FILE BY HAND IS NOT RECOMMENDED                                 | -->
<!-- =================================================================================== -->
<robot name="tm700" xmlns:xacro="http://www.ros.org/wiki/xacro">
  <gazebo>
    <plugin filename="libgazebo_ros_control.so" name="gazebo_ros_control">
      <!--robotNamespace>/</robotNamespace-->
      <!--robotSimType>gazebo_ros_control/DefaultRobotHWSim</robotSimType-->
      <legacyModeNS>true</legacyModeNS>
    </plugin>
    <!--
    <plugin name="gazebo_ros_power_monitor_controller" filename="libgazebo_ros_power_monitor.so">
      <alwaysOn>true</alwaysOn>
      <updateRate>1.0</updateRate>
      <timeout>5</timeout>
      <powerStateTopic>power_state</powerStateTopic>
      <powerStateRate>10.0</powerStateRate>
      <fullChargeCapacity>87.78</fullChargeCapacity>     
      <dischargeRate>-474</dischargeRate>
      <chargeRate>525</chargeRate>
      <dischargeVoltage>15.52</dischargeVoltage>
      <chargeVoltage>16.41</chargeVoltage>
    </plugin>
    -->
  </gazebo>
  <gazebo reference="base_link">
    <selfCollide>true</selfCollide>
  </gazebo>
  <gazebo reference="shoulder_1_link">
    <selfCollide>true</selfCollide>
  </gazebo>
  <gazebo reference="arm_1_link">
    <selfCollide>true</selfCollide>
  </gazebo>
  <gazebo reference="arm_2_link">
    <selfCollide>true</selfCollide>
  </gazebo>
  <gazebo reference="wrist_1_link">
    <selfCollide>true</selfCollide>
  </gazebo>
  <gazebo reference="wrist_2_link">
    <selfCollide>true</selfCollide>
  </gazebo>
  <gazebo reference="wrist_3_link">
    <selfCollide>true</selfCollide>
  </gazebo>
  <transmission name="shoulder_1_trans">
    <type>transmission_interface/SimpleTransmission</type>
    <joint name="shoulder_1_joint">
      <hardwareInterface>hardware_interface/PositionJointInterface</hardwareInterface>
    </joint>
    <actuator name="shoulder_1_motor">
      <mechanicalReduction>1</mechanicalReduction>
    </actuator>
  </transmission>
  <transmission name="shoulder_2_trans">
    <type>transmission_interface/SimpleTransmission</type>
    <joint name="shoulder_2_joint">
      <hardwareInterface>hardware_interface/PositionJointInterface</hardwareInterface>
    </joint>
    <actuator name="shoulder_2_motor">
      <mechanicalReduction>1</mechanicalReduction>
    </actuator>
  </transmission>
  <transmission name="elbow_1_trans">
    <type>transmission_interface/SimpleTransmission</type>
    <joint name="elbow_1_joint">
      <hardwareInterface>hardware_interface/PositionJointInterface</hardwareInterface>
    </joint>
    <actuator name="elbow_1_motor">
      <mechanicalReduction>1</mechanicalReduction>
    </actuator>
  </transmission>
  <transmission name="wrist_1_trans">
    <type>transmission_interface/SimpleTransmission</type>
    <joint name="wrist_1_joint">
      <hardwareInterface>hardware_interface/PositionJointInterface</hardwareInterface>
    </joint>
    <actuator name="wrist_1_motor">
      <mechanicalReduction>1</mechanicalReduction>
    </actuator>
  </transmission>
  <transmission name="wrist_2_trans">
    <type>transmission_interface/SimpleTransmission</type>
    <joint name="wrist_2_joint">
      <hardwareInterface>hardware_interface/PositionJointInterface</hardwareInterface>
    </joint>
    <actuator name="wrist_2_motor">
      <mechanicalReduction>1</mechanicalReduction>
    </actuator>
  </transmission>
  <transmission name="wrist_3_trans">
    <type>transmission_interface/SimpleTransmission</type>
    <joint name="wrist_3_joint">
      <hardwareInterface>hardware_interface/PositionJointInterface</hardwareInterface>
    </joint>
    <actuator name="wrist_3_motor">
      <mechanicalReduction>1</mechanicalReduction>
    </actuator>
  </transmission>
  <transmission name="finger_r_trans">
    <type>transmission_interface/SimpleTransmission</type>
    <joint name="finger_r_joint">
      <hardwareInterface>hardware_interface/PositionJointInterface</hardwareInterface>
    </joint>
    <actuator name="finger_r_motor">
      <mechanicalReduction>1</mechanicalReduction>
    </actuator>
  </transmission>
  <transmission name="finger_l_trans">
    <type>transmission_interface/SimpleTransmission</type>
    <joint name="finger_l_joint">
      <hardwareInterface>hardware_interface/PositionJointInterface</hardwareInterface>
    </joint>
    <actuator name="finger_l_motor">
      <mechanicalReduction>1</mechanicalReduction>
    </actuator>
  </transmission>
  <link name="base_link">
    <visual>
      <geometry>
        <mesh filename="./meshes/tm700/visual/Base.STL"/>
      </geometry>
      <material name="Grey">
        <color rgba="0.5 0.5 0.5 1.0"/>
      </material>
    </visual>
    <collision>
      <geometry>
        <mesh filename="./meshes/tm700/collision/base.STL"/>
      </geometry>
    </collision>
    <inertial>
      <mass value="1.0"/>
      <origin rpy="0 0 0" xyz="0.0 0.0 0.0"/>
      <inertia ixx="0.00110833289" ixy="0.0" ixz="0.0" iyy="0.00110833289" iyz="0.0" izz="0.0018"/>
    </inertial>
  </link>
  <link name="shoulder_1_link">
    <visual>
      <geometry>
        <mesh filename="./meshes/tm700/visual/Shoulder1.STL"/>
      </geometry>
      <material name="DarkOlive">
        <color rgba="0.3 0.3 0.25 1.0"/>
      </material>
    </visual>
    <collision>
      <geometry>
        <mesh filename="./meshes/tm700/collision/shoulder_1.STL"/>
      </geometry>
    </collision>
    <inertial>
      <mass value="4.5"/>
      <origin rpy="0 0 0" xyz="0.0 0.0 0.0"/>
      <inertia ixx="0.012487495005" ixy="0.0" ixz="0.0" iyy="0.012487495005" iyz="0.0" izz="0.0081"/>
    </inertial>
  </link>
  <joint name="shoulder_1_joint" type="revolute">
    <parent link="base_link"/>
    <child link="shoulder_1_link"/>
    <origin rpy="-1.570796325 0.0 0.0" xyz="0.0 0.0 0.1451"/>
    <axis xyz="0 -1 0"/>
    <limit effort="150.0" lower="-6.2831853" upper="6.2831853" velocity="3.15"/>
    <dynamics damping="0.0" friction="0.0"/>
  </joint>
  <link name="arm_1_link">
    <visual>
      <geometry>
        <mesh filename="./meshes/tm700/visual/Arm1.STL"/>
      </geometry>
      <material name="DarkOlive">
        <color rgba="0.3 0.3 0.25 1.0"/>
      </material>
    </visual>
    <collision>
      <geometry>
        <mesh filename="./meshes/tm700/collision/arm_1.STL"/>
      </geometry>
    </collision>
    <inertial>
      <mass value="10.5"/>
      <origin rpy="0 0 0" xyz="0.0 0.0 0.28"/>
      <inertia ixx="0.28384988646" ixy="0.0" ixz="0.0" iyy="0.28384988646" iyz="0.0" izz="0.0189"/>
    </inertial>
  </link>
  <joint name="shoulder_2_joint" type="revolute">
    <parent link="shoulder_1_link"/>
    <child link="arm_1_link"/>
    <origin rpy="0.0 0.0 -1.570796325" xyz="0.0 0.0 -0.146"/>
    <axis xyz="0 0 1"/>
    <limit effort="150.0" lower="-4.712388975" upper="4.712388975" velocity="3.15"/>
    <dynamics damping="0.0" friction="0.0"/>
  </joint>
  <link name="arm_2_link">
    <visual>
      <geometry>
        <mesh filename="./meshes/tm700/visual/Arm2.STL"/>
      </geometry>
      <material name="DarkOlive">
        <color rgba="0.3 0.3 0.25 1.0"/>
      </material>
    </visual>
    <collision>
      <geometry>
        <mesh filename="./meshes/tm700/collision/arm_2.STL"/>
      </geometry>
    </collision>
    <inertial>
      <mass value="2.1"/>
      <origin rpy="0 0 0" xyz="0.0 0.0 0.25"/>
      <inertia ixx="0.045639981744" ixy="0.0" ixz="0.0" iyy="0.045639981744" iyz="0.0" izz="0.00378"/>
    </inertial>
  </link>
  <joint name="elbow_1_joint" type="revolute">
    <parent link="arm_1_link"/>
    <child link="arm_2_link"/>
    <origin rpy="0.0 0.0 0.0" xyz="0.329 0.0 0.1298"/>
    <axis xyz="0 0 1"/>
    <limit effort="150.0" lower="-4.712388975" upper="4.712388975" velocity="3.15"/>
    <dynamics damping="0.0" friction="0.0"/>
  </joint>
  <link name="wrist_1_link">
    <visual>
      <geometry>
        <mesh filename="./meshes/tm700/visual/Wrist1.STL"/>
      </geometry>
      <material name="DarkOlive">
        <color rgba="0.3 0.3 0.25 1.0"/>
      </material>
    </visual>
    <collision>
      <geometry>
        <mesh filename="./meshes/tm700/collision/wrist_1.STL"/>
      </geometry>
    </collision>
    <inertial>
      <mass value="1.45"/>
      <origin rpy="0 0 0" xyz="0.0 0.0 0.0"/>
      <inertia ixx="0.132239947104" ixy="0.0" ixz="0.0" iyy="0.132239947104" iyz="0.0" izz="0.261"/>
    </inertial>
  </link>
  <joint name="wrist_1_joint" type="revolute">
    <parent link="arm_2_link"/>
    <child link="wrist_1_link"/>
    <origin rpy="1.570796325 0.0 1.570796325" xyz="0.3115 0.0 -0.106"/>
    <axis xyz="0 1 0"/>
    <limit effort="28.0" lower="-6.2831853" upper="6.2831853" velocity="3.2"/>
    <dynamics damping="0.0" friction="0.0"/>
  </joint>
  <link name="wrist_2_link">
    <visual>
      <geometry>
        <mesh filename="./meshes/tm700/visual/Wrist2.STL"/>
      </geometry>
      <material name="DarkOlive">
        <color rgba="0.3 0.3 0.25 1.0"/>
      </material>
    </visual>
    <collision>
      <geometry>
        <mesh filename="./meshes/tm700/collision/wrist_2.STL"/>
      </geometry>
    </collision>
    <inertial>
      <mass value="1.45"/>
      <origin rpy="0 0 0" xyz="0.0 0.0 0.0"/>
      <inertia ixx="0.132239947104" ixy="0.0" ixz="0.0" iyy="0.132239947104" iyz="0.0" izz="0.261"/>
    </inertial>
  </link>
  <joint name="wrist_2_joint" type="revolute">
    <parent link="wrist_1_link"/>
    <child link="wrist_2_link"/>
    <origin rpy="1.570796325 0.0 0.0" xyz="0.0 0.0 0.106"/>
    <axis xyz="0 1 0"/>
    <limit effort="28.0" lower="-6.2831853" upper="6.2831853" velocity="3.2"/>
    <dynamics damping="0.0" friction="0.0"/>
  </joint>
  <link name="wrist_3_link">
    <visual>
      <geometry>
        <mesh filename="./meshes/tm700/visual/Wrist3.STL"/>
      </geometry>
      <origin rpy="0 0 0" xyz="0 0 0.015"/>
      <material name="Grey">
        <color rgba="0.5 0.5 0.5 1.0"/>
      </material>
    </visual>
    <collision>
      <geometry>
        <mesh filename="./meshes/tm700/collision/wrist_3.STL"/>
      </geometry>
    </collision>
    <inertial>
      <mass value="0.4"/>
      <origin rpy="0 0 0" xyz="0.0 0.0 0.0"/>
      <inertia ixx="0.036479985408" ixy="0.0" ixz="0.0" iyy="0.036479985408" iyz="0.0" izz="0.072"/>
    </inertial>
  </link>
  <joint name="wrist_3_joint" type="revolute">
    <parent link="wrist_2_link"/>
    <child link="wrist_3_link"/>
    <origin rpy="0.0 0.0 0.0" xyz="0.0 0.0 0.0565"/>
    <axis xyz="0 0 1"/>
    <!-- Limited the wrist_3_joint to avoid crashing the gripper -->
    <limit effort="28.0" lower="-3.14159265" upper="3.14159265" velocity="3.2"/>
    <dynamics damping="0.0" friction="0.0"/>
  </joint>
  <link name="tip_link">
    <collision>
      <geometry>
        <box size="0.05 0.05 0.05"/>
      </geometry>
      <origin rpy="0 0 0" xyz="0 0 0.025"/>
    </collision>
  </link>
  <joint name="tip_fixed_joint" type="fixed">
    <parent link="wrist_3_link"/>
    <child link="tip_link"/>
    <origin rpy="0.0 0.0 0.0" xyz="0.0 0.0 0.0579"/>
  </joint>
  <!-- add compressing 2-jaw gripper -->
  <link name="gripper_link">
    <inertial>
      <origin rpy="0 0 0" xyz="0.0311572802112565 -1.25977280754998E-05 0.0092307003092138"/>
      <mass value="0.0795745052466434"/>
      <inertia ixx="3.27413333929741E-05" ixy="3.7314060486416E-08" ixz="3.97669066588691E-06" iyy="4.47182985231326E-05" iyz="-9.49992756213297E-09" izz="5.02142570756738E-05"/>
    </inertial>
    <visual>
      <origin rpy="0 3.14159265 0" xyz="0 0 0"/>
      <geometry>
        <mesh filename="./meshes/toyo_gripper/Gripper.STL" scale="0.01 0.01 0.01"/>
      </geometry>
      <material name="">
        <color rgba="0.792156862745098 0.819607843137255 0.933333333333333 1"/>
      </material>
    </visual>
    <collision>
      <origin rpy="0 3.14159265 0" xyz="0 0 0"/>
      <geometry>
        <mesh filename="./meshes/toyo_gripper/Gripper.STL" scale="0.01 0.01 0.01"/>
      </geometry>
    </collision>
  </link>
  <joint name="gripper_joint" type="fixed">
    <origin rpy="0 0 0" xyz="0 0 0.15"/>
    <parent link="wrist_3_link"/>
    <child link="gripper_link"/>
    <axis xyz="-1 0 0"/>
    <limit effort="1" lower="-1.57" upper="1.57" velocity="1"/>
  </joint>
  <link name="finger_r_link">
    <inertial>
      <origin rpy="0 0 0" xyz="0.0100191457715113 -0.00843835347348892 -0.00483280251641866"/>
      <mass value="0.0121931459003602"/>
      <inertia ixx="6.74016278931418E-07" ixy="-2.36459038775023E-07" ixz="3.1480125304693E-09" iyy="3.10966297287339E-06" iyz="1.19271018871704E-10" izz="2.77935600332309E-06"/>
    </inertial>
    <visual>
      <origin rpy="0 0 3.14159265" xyz="0 0 0"/>
      <geometry>
        <mesh filename="./meshes/toyo_gripper/finger_r.STL" scale="0.01 0.01 0.01"/>
      </geometry>
      <material name="">
        <color rgba="0.792156862745098 0.819607843137255 0.933333333333333 1"/>
      </material>
    </visual>
    <collision>
      <origin rpy="0 0 3.14159265" xyz="0 0 0"/>
      <geometry>
        <mesh filename="./meshes/toyo_gripper/finger_r.STL" scale="0.01 0.01 0.01"/>
      </geometry>
    </collision>
  </link>
  <!--prismatic-->
  <joint name="finger_r_joint" type="prismatic">
    <origin rpy="0 0 0" xyz="-0.0105 0.0015 0.013"/>
    <parent link="gripper_link"/>
    <child link="finger_r_link"/>
    <axis xyz="1 0 0"/>
    <limit effort="1" lower="-1" upper="0" velocity="1"/>
  </joint>
  <link name="finger_l_link">
    <inertial>
      <origin rpy="0 0 0" xyz="0.0100191599590265 0.00643833435729511 -0.00483280251641866"/>
      <mass value="0.0121931459003603"/>
      <inertia ixx="6.74017180959932E-07" ixy="2.3646368440071E-07" ixz="3.14801230297432E-09" iyy="3.10966207084492E-06" iyz="-1.19277023229564E-10" izz="2.77935600332313E-06"/>
    </inertial>
    <visual>
      <origin rpy="0 0 3.14159265" xyz="0 0 0"/>
      <geometry>
        <mesh filename="./meshes/toyo_gripper/finger_l.STL" scale="0.01 0.01 0.01"/>
      </geometry>
      <material name="">
        <color rgba="0.792156862745098 0.819607843137255 0.933333333333333 1"/>
      </material>
    </visual>
    <collision>
      <origin rpy="0 0 3.14159265" xyz="0 0 0"/>
      <geometry>
        <mesh filename="./meshes/toyo_gripper/finger_l.STL" scale="0.01 0.01 0.01"/>
      </geometry>
    </collision>
  </link>
  <!--prismatic-->
  <joint name="finger_l_joint" type="prismatic">
    <origin rpy="0 0 0" xyz="0.0105 0.0015 0.013"/>
    <parent link="gripper_link"/>
    <child link="finger_l_link"/>
    <axis xyz="1 0 0"/>
    <limit effort="1" lower="0" upper="1" velocity="1"/>
  </joint>
  <!-- add crabbing 2-jaw gripper-->
  <!--    <property name="gripper_length" value="0.1" />-->
  <!--    <property name="gripper_height" value="0.1" />-->
  <!--    <property name="gripper_right" value="0.05" />-->
  <!--    -->
  <!--    <link name="${prefix}finger_140_gripper_link">-->
  <!--      <visual>-->
  <!--        <origin xyz="0.0 0.0 0.0" rpy="0.0 0.0 0.0"/>-->
  <!--        <geometry>-->
  <!--          <mesh filename="./meshes/gripper/2_finger_140_gripper.STL" scale="0.001 0.001 0.001"/>-->
  <!--        </geometry>-->
  <!--        <material name="black">-->
  <!--          <color rgba="0.05 0.05 0.05 1"/>-->
  <!--        </material>-->
  <!--      </visual>-->
  <!--      <collision>-->
  <!--        <origin xyz="0.0 0.0 0.0" rpy="0.0 0.0 0.0"/>-->
  <!--        <geometry>-->
  <!--          <mesh filename="./meshes/gripper/2_finger_140_gripper.STL" scale="0.001 0.001 0.001"/>-->
  <!--        </geometry>-->
  <!--      </collision>-->
  <!--    </link>-->
  <!--    -->
  <!--    <joint name="${prefix}finger_140_gripper_joint" type="fixed">-->
  <!--      <parent link="${prefix}tip_link"/>-->
  <!--      <child link="${prefix}finger_140_gripper_link"/>-->
  <!--      <origin xyz="${gripper_right} ${gripper_height} ${gripper_length}" rpy="1.5707 1.5707 0.0"/>-->
  <!--    </joint>-->
  <!-- ROS base to TM 'base_link' Coordinates transform -->
  <link name="base"/>
  <joint name="base-base_link" type="fixed">
    <origin rpy="0 0 0" xyz="0 0 0"/>
    <parent link="base"/>
    <child link="base_link"/>
  </joint>
  <!-- Add plate link to avoid crashing into plate -->
  <link name="plate_link">
    <inertial>
      <origin rpy="0 0 0" xyz="0 0 0"/>
      <mass value="0.640128902693298"/>
      <inertia ixx="0.0212697824374231" ixy="-1.84819421839641E-07" ixz="0.00177278831625861" iyy="0.0200161122874848" iyz="1.82514218153984E-07" izz="0.00538401325307411"/>
    </inertial>
    <visual>
      <origin rpy="0 0 0" xyz="0 0 0"/>
      <geometry>
        <!--                <mesh filename="./meshes/plate.STL" />-->
        <box size="1.0 1.0 0.0001"/>
      </geometry>
      <material name="">
        <color rgba="0.792156862745098 0.819607843137255 0.933333333333333 1"/>
      </material>
    </visual>
    <collision>
      <origin rpy="0 0 0" xyz="0 0 0"/>
      <geometry>
        <!--                <mesh filename="./meshes/plate.STL"/>-->
        <box size="1.0 1.0 0.0001"/>
      </geometry>
    </collision>
  </link>
  <joint name="plate_joint" type="fixed">
    <origin rpy="0 0 0" xyz="-0.2 -0.4 0"/>
    <parent link="base"/>
    <child link="plate_link"/>
    <axis xyz="0 0 0"/>
  </joint>
  <!-- Add plate link to avoid crashing into experiment table -->
  <link name="table_plate_link">
    <inertial>
      <origin rpy="0 0 0" xyz="0.0 0 0.0"/>
      <mass value="0.640128902693298"/>
      <inertia ixx="0.0212697824374231" ixy="-1.84819421839641E-07" ixz="0.00177278831625861" iyy="0.0200161122874848" iyz="1.82514218153984E-07" izz="0.00538401325307411"/>
    </inertial>
    <visual>
      <origin rpy="0 0 0" xyz="0 0 0"/>
      <geometry>
        <!--                <mesh filename="./meshes/plate.STL" />-->
        <box size="1.0 1.0 0.0001"/>
      </geometry>
      <material name="">
        <color rgba="0.792156862745098 0.819607843137255 0.933333333333333 1"/>
      </material>
    </visual>
    <collision>
      <origin rpy="0 0 0" xyz="0 0 0"/>
      <geometry>
        <!--                <mesh filename="./meshes/plate.STL"/>-->
        <box size="1.0 1.0 0.0001"/>
      </geometry>
    </collision>
  </link>
  <joint name="table_plate_link" type="fixed">
    <origin rpy="0 0 0" xyz="0 0.8 -0.1"/>
    <parent link="base"/>
    <child link="table_plate_link"/>
    <axis xyz="0 0 0"/>
  </joint>
  <!-- Add support link to avoid crashing into Aluminum Scaffold-->
  <link name="support_link">
    <inertial>
      <origin rpy="0 0 0" xyz="0.0 0 0.0"/>
      <mass value="0.640128902693298"/>
      <inertia ixx="0.0212697824374231" ixy="-1.84819421839641E-07" ixz="0.00177278831625861" iyy="0.0200161122874848" iyz="1.82514218153984E-07" izz="0.00538401325307411"/>
    </inertial>
    <visual>
      <origin rpy="0 0 0" xyz="0 0 0"/>
      <geometry>
        <!--                <mesh filename="./meshes/plate.STL" />-->
        <box size="0.5 0.03 0.03"/>
      </geometry>
      <material name="">
        <color rgba="0.792156862745098 0.819607843137255 0.933333333333333 1"/>
      </material>
    </visual>
    <collision>
      <origin rpy="0 0 0" xyz="0 0 0"/>
      <geometry>
        <!--                <mesh filename="./meshes/plate.STL"/>-->
        <box size="0.5 0.03 0.03"/>
      </geometry>
    </collision>
  </link>
  <joint name="support_link" type="fixed">
    <origin rpy="0 0 1.570796325" xyz="0 0.7 0.82"/>
    <parent link="base"/>
    <child link="support_link"/>
    <axis xyz="0 0 0"/>
  </joint>
  <!-- Frame coincident with all-zeros TCP on TM controller -->
  <link name="tool0"/>
  <joint name="tip_link-tool0" type="fixed">
    <parent link="tip_link"/>
    <child link="tool0"/>
    <origin rpy="0 0 0" xyz="1 0 0"/>
  </joint>
  <link name="world"/>
  <joint name="world_joint" type="fixed">
    <parent link="world"/>
    <child link="base"/>
    <origin rpy="0 0 0" xyz="0 0 0"/>
  </joint>
</robot>
